Workbook

Sheet Dados
A1: ID | B1: Questão | C1: Gabarito | D1: Assunto | E1: Ano | F1: GPT 5 | G1: Gemini | H1: Claude Sonnet 4 | I1: Deepseek v3.1 | J1: Contem Imagem | K1: Contem Formula | L1: Contem Tabela | M1: Contem Codigo
A2: 1 | B2: 1 | C2: A | D2: Matemática | E2: 2019 | F2: A | G2: A | H2: A | I2: A | J2: 0 | K2: 1 | L2: 0 | M2: 0
A3: 2 | B3: 2 | C3: B | D3: Matemática | E3: 2019 | F3: B | G3: B | H3: B | I3: B | J3: 0 | K3: 1 | L3: 0 | M3: 0
A4: 3 | B4: 3 | C4: D | D4: Matemática | E4: 2019 | F4: D | G4: D | H4: D | I4: D | J4: 0 | K4: 1 | L4: 0 | M4: 0
A5: 4 | B5: 4 | C5: E | D5: Matemática | E5: 2019 | F5: E | G5: E | H5: E | I5: E | J5: 0 | K5: 1 | L5: 0 | M5: 0
A6: 5 | B6: 5 | C6: E | D6: Matemática | E6: 2019 | F6: E | G6: E | H6: E | I6: E | J6: 0 | K6: 1 | L6: 0 | M6: 0
A7: 6 | B7: 6 | C7: B | D7: Matemática | E7: 2019 | F7: B | G7: B | H7: B | I7: B | J7: 0 | K7: 1 | L7: 0 | M7: 0
A8: 7 | B8: 7 | C8: D | D8: Matemática | E8: 2019 | F8: D | G8: D | H8: D | I8: D | J8: 0 | K8: 1 | L8: 0 | M8: 0
A9: 8 | B9: 8 | C9: A | D9: Matemática | E9: 2019 | F9: A | G9: A | H9: A | I9: A | J9: 0 | K9: 1 | L9: 0 | M9: 0
A10: 9 | B10: 9 | C10: A | D10: Matemática | E10: 2019 | F10: A | G10: C | H10: A | I10: A | J10: 0 | K10: 1 | L10: 0 | M10: 0
A11: 10 | B11: 10 | C11: C | D11: Matemática | E11: 2019 | F11: C | G11: C | H11: C | I11: C | J11: 0 | K11: 1 | L11: 0 | M11: 0
A12: 11 | B12: 11 | C12: C | D12: Matemática | E12: 2019 | F12: C | G12: C | H12: C | I12: C | J12: 0 | K12: 0 | L12: 0 | M12: 0
A13: 12 | B13: 12 | C13: B | D13: Matemática | E13: 2019 | F13: B | G13: B | H13: B | I13: B | J13: 0 | K13: 0 | L13: 0 | M13: 0
... A28: 27 | B28: 27 | C28: A | D28: Fundamentos da Computação | E28: 2019 | F28: A | G28: A | H28: A | I28: A | J28: 0 | K28: 0 | L28: 0 | M28: 1
A29: 28 | B29: 28 | C29: * | D29: Fundamentos da Computação | E29: 2019 | J29: * | K29: * | L29: * | M29: *
A30: 29 | B30: 29 | C30: E | D30: Fundamentos da Computação | E30: 2019 | F30: E | G30: E | H30: E | I30: E | J30: 0 | K30: 0 | L30: 0 | M30: 0
A31: 30 | B31: 30 | C31: D | D31: Fundamentos da Computação | E31: 2019 | F31: D | G31: D | H31: D | I31: D | J31: 0 | K31: 0 | L31: 0 | M31: 0
A32: 31 | B32: 31 | C32: C | D32: Fundamentos da Computação | E32: 2019 | F32: C | G32: C | H32: C | I32: C | J32: 0 | K32: 0 | L32: 0 | M32: 1
A33: 32 | B33: 32 | C33: D | D33: Fundamentos da Computação | E33: 2019 | F33: D | G33: D | H33: D | I33: D | J33: 0 | K33: 0 | L33: 0 | M33: 0
A34: 33 | B34: 33 | C34: A | D34: Fundamentos da Computação | E34: 2019 | F34: A | G34: A | H34: A | I34: A | J34: 0 | K34: 0 | L34: 0 | M34: 0
A35: 34 | B35: 34 | C35: B | D35: Fundamentos da Computação | E35: 2019 | F35: E | G35: B | H35: B | I35: E | J35: 0 | K35: 0 | L35: 0 | M35: 0
A36: 35 | B36: 35 | C36: D | D36: Fundamentos da Computação | E36: 2019 | F36: D | G36: D | H36: D | I36: D | J36: 0 | K36: 0 | L36: 0 | M36: 0
A37: 36 | B37: 36 | C37: C | D37: Fundamentos da Computação | E37: 2019 | F37: C | G37: C | H37: C | I37: C | J37: 0 | K37: 0 | L37: 0 | M37: 0
A38: 37 | B38: 37 | C38: B | D38: Fundamentos da Computação | E38: 2019 | F38: B | G38: B | H38: B | I38: B | J38: 0 | K38: 0 | L38: 0 | M38: 0
A39: 38 | B39: 38 | C39: E | D39: Fundamentos da Computação | E39: 2019 | F39: E | G39: E | H39: E | I39: E | J39: 0 | K39: 0 | L39: 0 | M39: 0
A40: 39 | B40: 39 | C40: C | D40: Fundamentos da Computação | E40: 2019 | F40: C | G40: C | H40: C | I40: C | J40: 0 | K40: 1 | L40: 0 | M40: 0
A41: 40 | B41: 40 | C41: E | D41: Fundamentos da Computação | E41: 2019 | F41: E | G41: E | H41: E | I41: E | J41: 0 | K41: 0 | L41: 0 | M41: 0
... A71: 70 | B71: 70 | C71: D | D71: Tecnologia de Computadores | E71: 2019 | F71: B | G71: A | H71: B | I71: A | J71: 0 | K71: 0 | L71: 0 | M71: 0
A72: 71 | B72: 1 | C72: B | D72: Álgebra Linear | E72: 2022
A73: 72 | B73: 2 | C73: A | D73: Álgebra Linear | E73: 2022
A74: 73 | B74: 3 | C74: A | D74: Geometria Analítica | E74: 2022
A75: 74 | B75: 4 | C75: B | D75: Geometria Analítica | E75: 2022
A76: 75 | B76: 5 | C76: A | D76: Cálculo Diferencial e Integral | E76: 2022
A77: 76 | B77: 6 | C77: A | D77: Cálculo Diferencial e Integral | E77: 2022
A78: 77 | B78: 7 | C78: B | D78: Álgebra Linear | E78: 2022
A79: 78 | B79: 8 | C79: D | D79: Geometria Analítica | E79: 2022
A80: 79 | B80: 9 | C80: C | D80: Matemática Discreta | E80: 2022
A81: 80 | B81: 10 | C81: A | D81: Cálculo Diferencial e Integral | E81: 2022
A82: 81 | B82: 11 | C82: D | D82: Lógica Matemática | E82: 2022
A83: 82 | B83: 12 | C83: E | D83: Lógica Matemática | E83: 2022
...

Sheet Analise Parcial
B1: GPT 5 | C1: Gemini | D1: Claude Sonnet 4 | E1: Deepseek v3.1 | H1: C/ Imagem | I1: C/ Formula | J1: C/ Tabela | K1: C/ Codigo
A2: Acertos | B2: =SUMPRODUCT(--(Dados!C:C=Dados!F:F), --(Dados!F:F<>"")) -> 62 | C2: =SUMPRODUCT(--(Dados!C:C=Dados!G:G), --(Dados!G:G<>"")) -> 59 | D2: =SUMPRODUCT(--(Dados!C:C=Dados!H:H), --(Dados!H:H<>"")) -> 69 | E2: =SUMPRODUCT(--(Dados!C:C=Dados!I:I), --(Dados!I:I<>"")) -> 64 | G2: Total | H2: =SUM(Dados!J:J) -> 3 | I2: =SUM(Dados!K:K) -> 20 | J2: =SUM(Dados!L:L) -> 3 | K2: =SUM(Dados!M:M) -> 6
A3: Erros | B3: =SUMPRODUCT(--(Dados!C:C<>Dados!F:F), --(Dados!F:F<>"")) -> 8 | C3: =SUMPRODUCT(--(Dados!C:C<>Dados!G:G), --(Dados!G:G<>"")) -> 11 | D3: =SUMPRODUCT(--(Dados!C:C<>Dados!H:H), --(Dados!H:H<>"")) -> 9 | E3: =SUMPRODUCT(--(Dados!C:C<>Dados!I:I), --(Dados!I:I<>"")) -> 6
A4: Total | B4: =SUM(B2:B3) -> 70 | C4: =SUM(C2:C3) -> 70 | D4: =SUM(D2:D3) -> 78 | E4: =SUM(E2:E3) -> 70
A5: Taxa de Acerto | B5: =B2/B4 -> 0.88571429 | C5: =C2/C4 -> 0.84285714 | D5: =D2/D4 -> 0.88461538 | E5: =E2/E4 -> 0.91428571
A6: Acertos com Imagem | B6: =IFERROR(__xludf.DUMMYFUNCTION("QUERY(Dados!C:M, ""select count(C) where C = F and J = 1 and F is not null label count(C) ''"")"),2) -> 2 | C6: =IFERROR(__xludf.DUMMYFUNCTION("IFERROR(QUERY(Dados!C:M, ""select count(C) where C = G and J = 1 and G is not null label count(C) ''""),0)"),0) -> 0 | D6: =IFERROR(__xludf.DUMMYFUNCTION("IFERROR(QUERY(Dados!C:M, ""select count(C) where C = H and J = 1 and H is not null label count(C) ''""),0)"),1) -> 1 | E6: =IFERROR(__xludf.DUMMYFUNCTION("IFERROR(QUERY(Dados!C:M, ""select count(C) where C = I and J = 1 and I is not null label count(C) ''""),0)"),2) -> 2
A7: Acertos com Formula | B7: =IFERROR(__xludf.DUMMYFUNCTION("QUERY(Dados!C:M, ""select count(C) where C = F and K = 1 and F is not null label count(C) ''"")"),20) -> 20 | C7: =IFERROR(__xludf.DUMMYFUNCTION("IFERROR(QUERY(Dados!C:M, ""select count(C) where C = G and K = 1 and G is not null label count(C) ''""),0)"),17) -> 17 | D7: =IFERROR(__xludf.DUMMYFUNCTION("IFERROR(QUERY(Dados!C:M, ""select count(C) where C = H and K = 1 and H is not null label count(C) ''""),0)"),18) -> 18 | E7: =IFERROR(__xludf.DUMMYFUNCTION("IFERROR(QUERY(Dados!C:M, ""select count(C) where C = I and K = 1 and I is not null label count(C) ''""),0)"),20) -> 20
A8: Acertos com Tabela | B8: =IFERROR(__xludf.DUMMYFUNCTION("QUERY(Dados!C:M, ""select count(C) where C = F and L = 1 and F is not null label count(C) ''"")"),3) -> 3 | C8: =IFERROR(__xludf.DUMMYFUNCTION("IFERROR(QUERY(Dados!C:M, ""select count(C) where C = G and L = 1 and G is not null label count(C) ''""),0)"),3) -> 3 | D8: =IFERROR(__xludf.DUMMYFUNCTION("IFERROR(QUERY(Dados!C:M, ""select count(C) where C = H and L = 1 and H is not null label count(C) ''""),0)"),3) -> 3 | E8: =IFERROR(__xludf.DUMMYFUNCTION("IFERROR(QUERY(Dados!C:M, ""select count(C) where C = I and L = 1 and I is not null label count(C) ''""),0)"),3) -> 3
A9: Acertos com Codigo | B9: =IFERROR(__xludf.DUMMYFUNCTION("QUERY(Dados!C:M, ""select count(C) where C = F and M = 1 and F is not null label count(C) ''"")"),6) -> 6 | C9: =IFERROR(__xludf.DUMMYFUNCTION("IFERROR(QUERY(Dados!C:M, ""select count(C) where C = G and M = 1 and G is not null label count(C) ''""),0)"),6) -> 6 | D9: =IFERROR(__xludf.DUMMYFUNCTION("IFERROR(QUERY(Dados!C:M, ""select count(C) where C = H and M = 1 and H is not null label count(C) ''""),0)"),6) -> 6 | E9: =IFERROR(__xludf.DUMMYFUNCTION("IFERROR(QUERY(Dados!C:M, ""select count(C) where C = I and M = 1 and I is not null label count(C) ''""),0)"),6) -> 6
A10: % Imagem | B10: =B6/H2 -> 0.66666667 | C10: =C6/H2 -> 0 | D10: =D6/H2 -> 0.33333333 | E10: =E6/H2 -> 0.66666667
A11: %Formula | B11: =B7/I2 -> 1 | C11: =C7/I2 -> 0.85 | D11: =D7/I2 -> 0.9 | E11: =E7/I2 -> 1
A12: % Tabela | B12: =B8/J2 -> 1 | C12: =C8/J2 -> 1 | D12: =D8/J2 -> 1 | E12: =E8/J2 -> 1
A13: % Codigo | B13: =B9/K2 -> 1 | C13: =C9/K2 -> 1 | D13: =D9/K2 -> 1 | E13: =E9/K2 -> 1
A14: Desempenho Matematica | B14: =SUMPRODUCT(--(Dados!C2:C21=Dados!F2:F21), --(Dados!F2:F21<>"")) -> 19 | C14: =SUMPRODUCT(--(Dados!C2:C21=Dados!G2:G21), --(Dados!G2:G21<>"")) -> 17 | D14: =SUMPRODUCT(--(Dados!C2:C21=Dados!H2:H21), --(Dados!H2:H21<>"")) -> 20 | E14: =SUMPRODUCT(--(Dados!C2:C21=Dados!I2:I21), --(Dados!I2:I21<>"")) -> 20
A15: Desempenho Fundamentos Computação | B15: =SUMPRODUCT(--(Dados!C22:C51=Dados!F22:F51), --(Dados!F22:F51<>"")) -> 26 | C15: =SUMPRODUCT(--(Dados!C22:C51=Dados!G22:G51), --(Dados!G22:G51<>"")) -> 25 | D15: =SUMPRODUCT(--(Dados!C22:C51=Dados!H22:H51), --(Dados!H22:H51<>"")) -> 25 | E15: =SUMPRODUCT(--(Dados!C22:C51=Dados!I22:I51), --(Dados!I22:I51<>"")) -> 26
A16: Desempenho Tecnologia Computação | B16: =SUMPRODUCT(--(Dados!C52:C71=Dados!F52:F71), --(Dados!F52:F71<>"")) -> 17 | C16: =SUMPRODUCT(--(Dados!C4:C23=Dados!G4:G23), --(Dados!G4:G23<>"")) -> 17 | D16: =SUMPRODUCT(--(Dados!C52:C71=Dados!H52:H71), --(Dados!H52:H71<>"")) -> 16 | E16: =SUMPRODUCT(--(Dados!C52:C71=Dados!I52:I71), --(Dados!I52:I71<>"")) -> 18

Sheet Dados Humanos
